Traceback (most recent call last):
  File "D:\DEV\django_sprint3\venv\lib\site-packages\django\db\models\options.py", line 608, in get_field
    return self.fields_map[field_name]
KeyError: 'description'

During handling of the above exception, another exception occurred:

Traceback (most recent call last):
  File "D:\DEV\django_sprint3\venv\lib\site-packages\django\core\serializers\json.py", line 70, in Deserializer     
    yield from PythonDeserializer(objects, **options)
  File "D:\DEV\django_sprint3\venv\lib\site-packages\django\core\serializers\python.py", line 119, in Deserializer  
    field = Model._meta.get_field(field_name)
  File "D:\DEV\django_sprint3\venv\lib\site-packages\django\db\models\options.py", line 610, in get_field
    raise FieldDoesNotExist("%s has no field named '%s'" % (self.object_name, field_name))
django.core.exceptions.FieldDoesNotExist: Category has no field named 'description'

The above exception was the direct cause of the following exception:

Traceback (most recent call last):
  File "D:\DEV\django_sprint3\blogicum\manage.py", line 22, in <module>
    main()
  File "D:\DEV\django_sprint3\blogicum\manage.py", line 18, in main
    execute_from_command_line(sys.argv)
  File "D:\DEV\django_sprint3\venv\lib\site-packages\django\core\management\__init__.py", line 419, in execute_from_command_line
    utility.execute()
  File "D:\DEV\django_sprint3\venv\lib\site-packages\django\core\management\__init__.py", line 413, in execute      
    self.fetch_command(subcommand).run_from_argv(self.argv)
  File "D:\DEV\django_sprint3\venv\lib\site-packages\django\core\management\base.py", line 354, in run_from_argv    
    self.execute(*args, **cmd_options)
  File "D:\DEV\django_sprint3\venv\lib\site-packages\django\core\management\base.py", line 398, in execute
    output = self.handle(*args, **options)
  File "D:\DEV\django_sprint3\venv\lib\site-packages\django\core\management\commands\loaddata.py", line 78, in handle
    self.loaddata(fixture_labels)
  File "D:\DEV\django_sprint3\venv\lib\site-packages\django\core\management\commands\loaddata.py", line 123, in loaddata
    self.load_label(fixture_label)
  File "D:\DEV\django_sprint3\venv\lib\site-packages\django\core\management\commands\loaddata.py", line 181, in load_label
    for obj in objects:
  File "D:\DEV\django_sprint3\venv\lib\site-packages\django\core\serializers\json.py", line 74, in Deserializer     
    raise DeserializationError() from exc
django.core.serializers.base.DeserializationError: Problem installing fixture 'D:\DEV\django_sprint3\blogicum\db.json':
