Traceback (most recent call last):
  File "D:\DEV\django_sprint3\venv\lib\site-packages\django\db\backends\utils.py", line 84, in _execute
    return self.cursor.execute(sql, params)
  File "D:\DEV\django_sprint3\venv\lib\site-packages\django\db\backends\sqlite3\base.py", line 423, in execute
    return Database.Cursor.execute(self, query, params)
sqlite3.OperationalError: no such table: blog_category

The above exception was the direct cause of the following exception:

Traceback (most recent call last):
  File "D:\DEV\django_sprint3\blogicum\manage.py", line 22, in <module>
    main()
  File "D:\DEV\django_sprint3\blogicum\manage.py", line 18, in main
    execute_from_command_line(sys.argv)
  File "D:\DEV\django_sprint3\venv\lib\site-packages\django\core\management\__init__.py", line 419, in execute_from_command_line
    utility.execute()
  File "D:\DEV\django_sprint3\venv\lib\site-packages\django\core\management\__init__.py", line 413, in execute
    self.fetch_command(subcommand).run_from_argv(self.argv)
  File "D:\DEV\django_sprint3\venv\lib\site-packages\django\core\management\base.py", line 354, in run_from_argv
    self.execute(*args, **cmd_options)
  File "D:\DEV\django_sprint3\venv\lib\site-packages\django\core\management\base.py", line 398, in execute
    output = self.handle(*args, **options)
  File "D:\DEV\django_sprint3\venv\lib\site-packages\django\core\management\commands\loaddata.py", line 78, in handle
    self.loaddata(fixture_labels)
  File "D:\DEV\django_sprint3\venv\lib\site-packages\django\core\management\commands\loaddata.py", line 123, in loaddata
    self.load_label(fixture_label)
  File "D:\DEV\django_sprint3\venv\lib\site-packages\django\core\management\commands\loaddata.py", line 190, in load_label
    obj.save(using=self.using)
  File "D:\DEV\django_sprint3\venv\lib\site-packages\django\core\serializers\base.py", line 223, in save
    models.Model.save_base(self.object, using=using, raw=True, **kwargs)
  File "D:\DEV\django_sprint3\venv\lib\site-packages\django\db\models\base.py", line 776, in save_base
    updated = self._save_table(
  File "D:\DEV\django_sprint3\venv\lib\site-packages\django\db\models\base.py", line 858, in _save_table
    updated = self._do_update(base_qs, using, pk_val, values, update_fields,        
  File "D:\DEV\django_sprint3\venv\lib\site-packages\django\db\models\base.py", line 912, in _do_update
    return filtered._update(values) > 0
  File "D:\DEV\django_sprint3\venv\lib\site-packages\django\db\models\query.py", line 802, in _update
    return query.get_compiler(self.db).execute_sql(CURSOR)
  File "D:\DEV\django_sprint3\venv\lib\site-packages\django\db\models\sql\compiler.py", line 1559, in execute_sql
    cursor = super().execute_sql(result_type)
  File "D:\DEV\django_sprint3\venv\lib\site-packages\django\db\models\sql\compiler.py", line 1175, in execute_sql
    cursor.execute(sql, params)
  File "D:\DEV\django_sprint3\venv\lib\site-packages\django\db\backends\utils.py", line 98, in execute
    return super().execute(sql, params)
  File "D:\DEV\django_sprint3\venv\lib\site-packages\django\db\backends\utils.py", line 66, in execute
    return self._execute_with_wrappers(sql, params, many=False, executor=self._execute)
  File "D:\DEV\django_sprint3\venv\lib\site-packages\django\db\backends\utils.py", line 75, in _execute_with_wrappers
    return executor(sql, params, many, context)
  File "D:\DEV\django_sprint3\venv\lib\site-packages\django\db\backends\utils.py", line 84, in _execute
    return self.cursor.execute(sql, params)
  File "D:\DEV\django_sprint3\venv\lib\site-packages\django\db\utils.py", line 90, in __exit__
    raise dj_exc_value.with_traceback(traceback) from exc_value
  File "D:\DEV\django_sprint3\venv\lib\site-packages\django\db\backends\utils.py", line 84, in _execute
    return self.cursor.execute(sql, params)
  File "D:\DEV\django_sprint3\venv\lib\site-packages\django\db\backends\sqlite3\base.py", line 423, in execute
    return Database.Cursor.execute(self, query, params)
django.db.utils.OperationalError: Problem installing fixture 'D:\DEV\django_sprint3\blogicum\db.json': Could not load blog.Category(pk=1): no such table: blog_category 
(venv) 
